Workbook

Sheet AUG24
B1: Opening balance | C1: Purchases | D1: Debit Notes | E1: Inventory Write-offs | F1: Sales | G1: Credit Note | H1: Closing balance
A2: MI0001 - 4515-Wx Hendred Brake Lining | B2: 138.25 | C2: 1292 | D2: 0 | E2: 0 | F2: -211.75 | G2: 0 | H2: 1218.5
A3: MI0002 - MP31 | B3: 0.25 | C3: 0 | D3: 0 | E3: 0 | F3: 0 | G3: 0 | H3: 0.25
A4: MI0003 - MP32 | B4: -3 | C4: 26 | D4: 0 | E4: 0 | F4: -4 | G4: 0 | H4: 19
A5: MI0004 - MP36 | B5: 172.75 | C5: 64 | D5: 0 | E5: 0 | F5: -5 | G5: 0 | H5: 231.75
A6: MI0005 - BC36 | B6: 258.25 | C6: 0 | D6: 0 | E6: -0.125 | F6: -19.5 | G6: 0 | H6: 238.625
A7: MI0008 - 996075-K AIRBAG VOLVO O/M 1076076 | B7: 2 | C7: 0 | D7: 0 | E7: 0 | F7: 0 | G7: 0 | H7: 2
A8: MI0009 - 994713-K AIRBAG VOLVO O/M 1076595 | B8: 1 | C8: 0 | D8: 0 | E8: 0 | F8: 0 | G8: 0 | H8: 1
A9: MI0010 - 994913-K AIRBAG SCA 124 DIFF / 9881 | B9: 17 | C9: 0 | D9: 0 | E9: 0 | F9: 0 | G9: 0 | H9: 17
A10: MI0011 - 999780-K AIRBAG FREIGHTLINER METAL | B10: 76 | C10: 0 | D10: 0 | E10: 0 | F10: -4 | G10: 0 | H10: 72
A11: MI0018 - BPW SPRING LONG | B11: 5 | C11: 0 | D11: 0 | E11: 0 | F11: 0 | G11: 0 | H11: 5
A12: MI0019 - OIL SEAL 125 X 150 X 13 | B12: 40 | C12: 0 | D12: 0 | E12: 0 | F12: 0 | G12: 0 | H12: 40
A13: MI0021 - H24W05 | B13: 7 | C13: 0 | D13: 0 | E13: 0 | F13: 0 | G13: 0 | H13: 7
... A482: MI0645 - TIP INJECTOR FAW | B482: 0 | C482: 0 | D482: 0 | E482: 0 | F482: -6 | G482: 0 | H482: -6
A483: MI0646 - 530W SOLAR PANEL - SLR | B483: 0 | C483: 40 | D483: 0 | E483: 0 | F483: 27/Nov/99 | G483: 0 | H483: 7
A484: MI0647 - 525W SOLAR PANEL - SLR | B484: 0 | C484: 67 | D484: 0 | E484: 0 | F484: 0 | G484: 0 | H484: 67
B486: 49100.75 | C486: 13289 | D486: 27/Dec/99 | E486: 20/Dec/99 | F486: 3/Apr/69 | G486: 51 | H486: 51200.375

Sheet SEP24
A1: .
A2: Inventory Quantity Summary
A3: For the period from 01.09.2024 to 30.09.2024
B4: Opening balance | C4: Purchases | D4: Debit Notes | E4: Inventory Write-offs | F4: Sales | G4: Credit Note | H4: Closing balance
A6: MI0001 - 4515-Wx Hendred Brake Lining | B6: 1212.5 | C6: 0 | D6: 0 | E6: 0 | F6: -132.75 | G6: 0 | H6: 1079.75
A7: MI0002 - MP31 | B7: 0.25 | C7: 0 | D7: 0 | E7: 0 | F7: 0 | G7: 0 | H7: 0.25
A8: MI0003 - MP32 | B8: 17 | C8: 0 | D8: 0 | E8: -2 | F8: -10 | G8: 0 | H8: 5
A9: MI0004 - MP36 | B9: 231.75 | C9: 0 | D9: 0 | E9: 0 | F9: -6 | G9: 0 | H9: 225.75
A10: MI0005 - BC36 | B10: 235.625 | C10: 0 | D10: 0 | E10: -3.5 | F10: -19 | G10: 0 | H10: 213.125
A11: MI0008 - 996075-K AIRBAG VOLVO O/M 1076076 | B11: 2 | C11: 0 | D11: 0 | E11: 0 | F11: 0 | G11: 0 | H11: 2
A12: MI0009 - 994713-K AIRBAG VOLVO O/M 1076595 | B12: 1 | C12: 0 | D12: 0 | E12: 0 | F12: 0 | G12: 0 | H12: 1
A13: MI0010 - 994913-K AIRBAG SCA 124 DIFF / 9881 | B13: 17 | C13: 0 | D13: 0 | E13: 0 | F13: -1 | G13: 0 | H13: 16
A14: MI0011 - 999780-K AIRBAG FREIGHTLINER METAL | B14: 72 | C14: 0 | D14: 0 | E14: 0 | F14: -1 | G14: 0 | H14: 71
A15: MI0018 - BPW SPRING LONG | B15: 5 | C15: 0 | D15: 0 | E15: 0 | F15: 0 | G15: 0 | H15: 5
A16: MI0019 - OIL SEAL 125 X 150 X 13 | B16: 40 | C16: 0 | D16: 0 | E16: 0 | F16: 0 | G16: 0 | H16: 40
A17: MI0021 - H24W05 | B17: 7 | C17: 0 | D17: 0 | E17: 0 | F17: 0 | G17: 0 | H17: 7
... A492: MI0657 - LITHIUM BATTERY 12V 100AH - SLR | B492: 0 | C492: 12 | D492: 0 | E492: 0 | F492: -6 | G492: 0 | H492: 6
B494: 51136.375 | C494: 15237 | D494: -17 | E494: -39.5 | F494: -8994.25 | G494: 41 | H494: 57363.625

Sheet OCT24
A1: .
A2: Inventory Quantity Summary
A3: For the period from 01.10.2024 to 31.10.2024
B4: Opening balance | C4: Purchases | D4: Debit Notes | E4: Inventory Write-offs | F4: Sales | G4: Credit Note | H4: Closing balance
A6: MI0001 - 4515-Wx Hendred Brake Lining | B6: 1079.75 | C6: 0 | D6: 0 | E6: 0 | F6: -188.5 | G6: 0 | H6: 891.25
A7: MI0002 - MP31 | B7: 0.25 | C7: 0 | D7: 0 | E7: 0 | F7: 0 | G7: 0 | H7: 0.25
A8: MI0003 - MP32 | B8: 5 | C8: 0 | D8: 0 | E8: 0 | F8: -6 | G8: 0 | H8: -1
A9: MI0004 - MP36 | B9: 225.75 | C9: 0 | D9: 0 | E9: 0 | F9: -4 | G9: 0 | H9: 221.75
A10: MI0005 - BC36 | B10: 213.125 | C10: 0 | D10: 0 | E10: 0 | F10: -30.5 | G10: 0 | H10: 182.625
A11: MI0008 - 996075-K AIRBAG VOLVO O/M 1076076 | B11: 2 | C11: 0 | D11: 0 | E11: 0 | F11: 0 | G11: 0 | H11: 2
A12: MI0009 - 994713-K AIRBAG VOLVO O/M 1076595 | B12: 1 | C12: 0 | D12: 0 | E12: 0 | F12: -1 | G12: 0 | H12: 0
A13: MI0010 - 994913-K AIRBAG SCA 124 DIFF / 9881 | B13: 16 | C13: 0 | D13: 0 | E13: 0 | F13: 0 | G13: 0 | H13: 16
A14: MI0011 - 999780-K AIRBAG FREIGHTLINER METAL | B14: 71 | C14: 0 | D14: 0 | E14: 0 | F14: -9 | G14: 0 | H14: 62
A15: MI0018 - BPW SPRING LONG | B15: 5 | C15: 0 | D15: 0 | E15: 0 | F15: 0 | G15: 0 | H15: 5
A16: MI0019 - OIL SEAL 125 X 150 X 13 | B16: 40 | C16: 0 | D16: 0 | E16: 0 | F16: 0 | G16: 0 | H16: 40
A17: MI0021 - H24W05 | B17: 7 | C17: 0 | D17: 0 | E17: 0 | F17: 0 | G17: 0 | H17: 7
... A490: MI0660 - 410W SOLAR PANEL - SLR | B490: 0 | C490: 0 | D490: 0 | E490: 0 | F490: -1 | G490: 0 | H490: -1
B492: 57363.625 | C492: 6823 | D492: -11 | E492: -6 | F492: -11374.75 | G492: 12 | H492: 52806.875

Sheet NOV24
A1: .
A2: Inventory Quantity Summary
A3: For the period from 01.11.2024 to 30.11.2024
B4: Opening balance | C4: Purchases | D4: Debit Notes | E4: Inventory Write-offs | F4: Sales | G4: Credit Note | H4: Closing balance
A6: MI0001 - 4515-Wx Hendred Brake Lining | B6: 891.25 | C6: 1308 | D6: 0 | E6: -0.125 | F6: -228.75 | G6: 0 | H6: 1970.375
A7: MI0002 - MP31 | B7: 0.25 | C7: 0 | D7: 0 | E7: 0 | F7: 0 | G7: 0 | H7: 0.25
A8: MI0003 - MP32 | B8: -1 | C8: 52 | D8: 0 | E8: 0 | F8: -12 | G8: 0 | H8: 39
A9: MI0004 - MP36 | B9: 221.75 | C9: 0 | D9: 0 | E9: 0 | F9: -7 | G9: 0 | H9: 214.75
A10: MI0005 - BC36 | B10: 182.625 | C10: 0 | D10: 0 | E10: 0 | F10: -38.5 | G10: 0 | H10: 144.125
A11: MI0008 - 996075-K AIRBAG VOLVO O/M 1076076 | B11: 2 | C11: 0 | D11: 0 | E11: 0 | F11: 0 | G11: 0 | H11: 2
A12: MI0009 - 994713-K AIRBAG VOLVO O/M 1076595 | B12: 1 | C12: 0 | D12: 0 | E12: 0 | F12: 0 | G12: 0 | H12: 1
A13: MI0010 - 994913-K AIRBAG SCA 124 DIFF / 9881 | B13: 16 | C13: 0 | D13: 0 | E13: 0 | F13: 0 | G13: 0 | H13: 16
A14: MI0011 - 999780-K AIRBAG FREIGHTLINER METAL | B14: 62 | C14: 0 | D14: 0 | E14: 0 | F14: -22 | G14: 0 | H14: 40
A15: MI0018 - BPW SPRING LONG | B15: 5 | C15: 100 | D15: 0 | E15: 0 | F15: -2 | G15: 0 | H15: 103
A16: MI0019 - OIL SEAL 125 X 150 X 13 | B16: 40 | C16: 0 | D16: 0 | E16: 0 | F16: 0 | G16: 0 | H16: 40
A17: MI0021 - H24W05 | B17: 7 | C17: 0 | D17: 0 | E17: 0 | F17: 0 | G17: 0 | H17: 7
... A506: MI0674 - L11 RIVET | B506: 0 | C506: 20000 | D506: 0 | E506: 0 | F506: 0 | G506: 0 | H506: 20000
B508: 52849.125 | C508: 39940 | D508: -1 | E508: -9.375 | F508: -10200.75 | G508: 21 | H508: 82599

Sheet DEC24
A1: .
A2: Inventory Quantity Summary
A3: For the period from 01.12.2024 to 31.12.2024
B4: Opening balance | C4: Purchases | D4: Inventory Write-offs | E4: Sales | F4: Credit Note | G4: Closing balance
A6: MI0001 - 4515-Wx Hendred Brake Lining | B6: 1970.375 | C6: 0 | D6: 0 | E6: -169.5 | F6: 0 | G6: 1800.875
A7: MI0002 - MP31 | B7: 0.25 | C7: 0 | D7: 0 | E7: 0 | F7: 0 | G7: 0.25
A8: MI0003 - MP32 | B8: 39 | C8: 0 | D8: -2.5 | E8: -27.75 | F8: 0 | G8: 8.75
A9: MI0004 - MP36 | B9: 214.75 | C9: 0 | D9: -0.125 | E9: -2.5 | F9: 0 | G9: 212.125
A10: MI0005 - BC36 | B10: 144.125 | C10: 0 | D10: 0 | E10: -32.75 | F10: 0 | G10: 111.375
A11: MI0008 - 996075-K AIRBAG VOLVO O/M 1076076 | B11: 2 | C11: 0 | D11: 0 | E11: 0 | F11: 0 | G11: 2
A12: MI0009 - 994713-K AIRBAG VOLVO O/M 1076595 | B12: 1 | C12: 0 | D12: 0 | E12: 0 | F12: 0 | G12: 1
A13: MI0010 - 994913-K AIRBAG SCA 124 DIFF / 9881 | B13: 16 | C13: 0 | D13: 0 | E13: -1 | F13: 0 | G13: 15
A14: MI0011 - 999780-K AIRBAG FREIGHTLINER METAL | B14: 40 | C14: 0 | D14: 0 | E14: -18 | F14: 0 | G14: 22
A15: MI0018 - BPW SPRING LONG | B15: 103 | C15: 0 | D15: 0 | E15: 0 | F15: 0 | G15: 103
A16: MI0019 - OIL SEAL 125 X 150 X 13 | B16: 40 | C16: 0 | D16: 0 | E16: 0 | F16: 0 | G16: 40
A17: MI0021 - H24W05 | B17: 7 | C17: 0 | D17: 0 | E17: 0 | F17: 0 | G17: 7
... A509: MI0682 - 225/45R19 PCR TYRE | B509: 0 | C509: 100 | D509: 0 | E509: 0 | F509: 0 | G509: 100
B511: 82610 | C511: 8321 | D511: -9.625 | E511: -12722.875 | F511: 13 | G511: 78211.5

Sheet JAN25
A1: For the period from 01.01.2025 to 31.01.2025 | B1: Opening balance | C1: Purchases | D1: Inventory Write-offs | E1: Sales | F1: Credit Note | G1: Closing balance
A2: MI0001 - 4515-Wx Hendred Brake Lining | B2: 1800.875 | C2: 0 | D2: 0 | E2: -189.75 | F2: 0 | G2: 1611.125
A3: MI0002 - MP31 | B3: 0.25 | C3: 0 | D3: 0 | E3: 0 | F3: 0 | G3: 0.25
A4: MI0003 - MP32 | B4: 8.75 | C4: 4 | D4: 0 | E4: -5 | F4: 0 | G4: 7.75
A5: MI0004 - MP36 | B5: 212.125 | C5: 0 | D5: 0 | E5: -13.25 | F5: 0 | G5: 198.875
A6: MI0005 - BC36 | B6: 111.375 | C6: 0 | D6: 0 | E6: -35.75 | F6: 0 | G6: 75.625
A7: MI0008 - 996075-K AIRBAG VOLVO O/M 1076076 | B7: 2 | C7: 0 | D7: 0 | E7: 0 | F7: 0 | G7: 2
A8: MI0009 - 994713-K AIRBAG VOLVO O/M 1076595 | B8: 1 | C8: 0 | D8: 0 | E8: 0 | F8: 0 | G8: 1
A9: MI0010 - 994913-K AIRBAG SCA 124 DIFF / 9881 | B9: 15 | C9: 0 | D9: 0 | E9: 0 | F9: 0 | G9: 15
A10: MI0011 - 999780-K AIRBAG FREIGHTLINER METAL | B10: 22 | C10: 0 | D10: 0 | E10: -13 | F10: 0 | G10: 9
A11: MI0018 - BPW SPRING LONG | B11: 103 | C11: 200 | D11: 0 | E11: -26 | F11: 0 | G11: 277
A12: MI0019 - OIL SEAL 125 X 150 X 13 | B12: 40 | C12: 0 | D12: 0 | E12: 0 | F12: 0 | G12: 40
A13: MI0021 - H24W05 | B13: 7 | C13: 0 | D13: 0 | E13: 0 | F13: 0 | G13: 7
... A517: MI0697 - 24Volt 2500 Solar-Hybrid Inverter Sukam | B517: 0 | C517: 3 | D517: 0 | E517: -1 | F517: 0 | G517: 2
B519: 78211.5 | C519: 17261 | D519: -12 | E519: -10635.75 | F519: 60 | G519: 84884.75

Sheet FEB25
A1: For the period from 01.02.2025 to 28.02.2025 | B1: Opening balance | C1: Purchases | D1: Inventory Write-offs | E1: Sales | F1: Credit Note | G1: Closing balance
A2: MI0001 - 4515-Wx Hendred Brake Lining | B2: 1608.125 | C2: 0 | D2: 0 | E2: -220 | F2: 0 | G2: 1388.125
A3: MI0002 - MP31 | B3: 0.25 | C3: 0 | D3: 0 | E3: 0 | F3: 0 | G3: 0.25
A4: MI0003 - MP32 | B4: 7.75 | C4: 10 | D4: 0 | E4: -11.25 | F4: 0 | G4: 6.5
A5: MI0004 - MP36 | B5: 198.875 | C5: 0 | D5: 0 | E5: -20.5 | F5: 0 | G5: 178.375
A6: MI0005 - BC36 | B6: 75.625 | C6: 0 | D6: 0 | E6: -27 | F6: 0 | G6: 48.625
A7: MI0008 - 996075-K AIRBAG VOLVO O/M 1076076 | B7: 2 | C7: 0 | D7: 0 | E7: 0 | F7: 0 | G7: 2
A8: MI0009 - 994713-K AIRBAG VOLVO O/M 1076595 | B8: 1 | C8: 0 | D8: 0 | E8: 0 | F8: 0 | G8: 1
A9: MI0010 - 994913-K AIRBAG SCA 124 DIFF / 9881 | B9: 15 | C9: 0 | D9: 0 | E9: 0 | F9: 0 | G9: 15
A10: MI0011 - 999780-K AIRBAG FREIGHTLINER METAL | B10: 9 | C10: 0 | D10: 0 | E10: 0 | F10: 0 | G10: 9
A11: MI0018 - BPW SPRING LONG | B11: 277 | C11: 0 | D11: 0 | E11: -1 | F11: 0 | G11: 276
A12: MI0019 - OIL SEAL 125 X 150 X 13 | B12: 40 | C12: 0 | D12: 0 | E12: 0 | F12: 0 | G12: 40
A13: MI0021 - H24W05 | B13: 7 | C13: 0 | D13: 0 | E13: 0 | F13: 0 | G13: 7
... A512: MI0698 - 285/60R18 PCR TYRE | B512: 0 | C512: 100 | D512: 0 | E512: 0 | F512: 0 | G512: 100
B514: 84779.75 | C514: 14610 | D514: -33 | E514: -12531.25 | F514: 10 | G514: 86835.5

Sheet MAR25
A1: For the period from 01.03.2025 to 31.03.2025 | B1: Opening balance | C1: Purchases | D1: Inventory Write-offs | E1: Sales | F1: Credit Note | G1: Closing balance
A2: MI0001 - 4515-Wx Hendred Brake Lining | B2: 1412.875 | C2: 0 | D2: 0 | E2: -272 | F2: 0 | G2: 1140.875
A3: MI0002 - MP31 | B3: 0.25 | C3: 0 | D3: 0 | E3: 0 | F3: 0 | G3: 0.25
A4: MI0003 - MP32 | B4: 6.5 | C4: 1 | D4: 0 | E4: -6.5 | F4: 0 | G4: 1
A5: MI0004 - MP36 | B5: 178.375 | C5: 0 | D5: 0 | E5: 0 | F5: 0 | G5: 178.375
A6: MI0005 - BC36 | B6: 48.625 | C6: 0 | D6: 0 | E6: -11.875 | F6: 0 | G6: 36.75
A7: MI0008 - 996075-K AIRBAG VOLVO O/M 1076076 | B7: 2 | C7: 0 | D7: 0 | E7: 0 | F7: 0 | G7: 2
A8: MI0009 - 994713-K AIRBAG VOLVO O/M 1076595 | B8: 1 | C8: 20 | D8: 0 | E8: -2 | F8: 0 | G8: 19
A9: MI0010 - 994913-K AIRBAG SCA 124 DIFF / 9881 | B9: 15 | C9: 2 | D9: 0 | E9: -2 | F9: 0 | G9: 15
A10: MI0011 - 999780-K AIRBAG FREIGHTLINER METAL | B10: 9 | C10: 10 | D10: 0 | E10: -5 | F10: 0 | G10: 14
A11: MI0013 - 994183-24K AIRBAG BENZ | B11: 0 | C11: 0 | D11: 0 | E11: -14 | F11: 0 | G11: -14
A12: MI0018 - BPW SPRING LONG | B12: 276 | C12: 0 | D12: 0 | E12: -20 | F12: 0 | G12: 256
A13: MI0019 - OIL SEAL 125 X 150 X 13 | B13: 40 | C13: 0 | D13: 0 | E13: 0 | F13: 0 | G13: 40
... A520: MI0701 - P255/50R19 | B520: 0 | C520: 50 | D520: 0 | E520: 0 | F520: 0 | G520: 50
B522: 88493.25 | C522: 9564 | D522: -5 | E522: -13783.125 | F522: 84 | G522: 84353.125

Sheet APR25
A1: For the period from 01.04.2025 to 30.04.2025 | B1: Opening balance | C1: Purchases | D1: Inventory Write-offs | E1: Sales | F1: Credit Note | G1: Closing balance
A2: MI0001 - 4515-Wx Hendred Brake Lining | B2: 1138.125 | C2: 0 | D2: 0 | E2: -245.25 | F2: 0 | G2: 892.875
A3: MI0002 - MP31 | B3: 0.25 | C3: 0 | D3: 0 | E3: 0 | F3: 0 | G3: 0.25
A4: MI0003 - MP32 | B4: 1 | C4: 6 | D4: 0 | E4: -5 | F4: 0 | G4: 2
A5: MI0004 - MP36 | B5: 178.375 | C5: 0 | D5: 0 | E5: -3.5 | F5: 0 | G5: 174.875
A6: MI0005 - BC36 | B6: 36.75 | C6: 0 | D6: -3.5 | E6: -9 | F6: 0 | G6: 24.25
A7: MI0008 - 996075-K AIRBAG VOLVO O/M 1076076 | B7: 2 | C7: 0 | D7: 0 | E7: 0 | F7: 0 | G7: 2
A8: MI0009 - 994713-K AIRBAG VOLVO O/M 1076595 | B8: 19 | C8: 0 | D8: 0 | E8: 0 | F8: 0 | G8: 19
A9: MI0010 - 994913-K AIRBAG SCA 124 DIFF / 9881 | B9: 15 | C9: 0 | D9: 0 | E9: 0 | F9: 0 | G9: 15
A10: MI0011 - 999780-K AIRBAG FREIGHTLINER METAL | B10: 14 | C10: 10 | D10: 0 | E10: -15 | F10: 0 | G10: 9
A11: MI0013 - 994183-24K AIRBAG BENZ | B11: -14 | C11: 0 | D11: 0 | E11: 0 | F11: 0 | G11: -14
A12: MI0018 - BPW SPRING LONG | B12: 256 | C12: 0 | D12: 0 | E12: -1 | F12: 0 | G12: 255
A13: MI0019 - OIL SEAL 125 X 150 X 13 | B13: 40 | C13: 0 | D13: 0 | E13: 0 | F13: 0 | G13: 40
... A526: MI0702 - JY-12.00R20 DIFF TYRE JD681 | B526: 50 | C526: 0 | D526: 0 | E526: 0 | F526: 0 | G526: 50
B528: 85032.375 | C528: 4347 | D528: -6.5 | E528: -13192.5 | F528: 47 | G528: 76227.375

Sheet MAY25
A1: For the period from 01.05.2025 to 31.05.2025 | B1: Opening balance | C1: Purchases | D1: Inventory Write-offs | E1: Sales | F1: Credit Note | G1: Closing balance
A2: MI0001 - 4515-Wx Hendred Brake Lining | B2: 892.875 | C2: 0 | D2: 0 | E2: -257.25 | F2: 0 | G2: 635.625
A3: MI0002 - MP31 | B3: 0.25 | C3: 0 | D3: 0 | E3: 0 | F3: 0 | G3: 0.25
A4: MI0003 - MP32 | B4: 2 | C4: 8 | D4: 0 | E4: -8 | F4: 0 | G4: 2
A5: MI0004 - MP36 | B5: 174.875 | C5: 0 | D5: 0 | E5: -17 | F5: 0 | G5: 157.875
A6: MI0005 - BC36 | B6: 24.25 | C6: 26 | D6: 0 | E6: -20.5 | F6: 0 | G6: 29.75
A7: MI0008 - 996075-K AIRBAG VOLVO O/M 1076076 | B7: 2 | C7: 0 | D7: 0 | E7: 0 | F7: 0 | G7: 2
A8: MI0009 - 994713-K AIRBAG VOLVO O/M 1076595 | B8: 19 | C8: 0 | D8: 0 | E8: -6 | F8: 0 | G8: 13
A9: MI0010 - 994913-K AIRBAG SCA 124 DIFF / 9881 | B9: 15 | C9: 0 | D9: 0 | E9: -1 | F9: 0 | G9: 14
A10: MI0011 - 999780-K AIRBAG FREIGHTLINER METAL | B10: 9 | C10: 0 | D10: 0 | E10: -7 | F10: 0 | G10: 2
A11: MI0013 - 994183-24K AIRBAG BENZ | B11: -14 | C11: 0 | D11: 0 | E11: 0 | F11: 0 | G11: -14
A12: MI0018 - BPW SPRING LONG | B12: 255 | C12: 0 | D12: 0 | E12: 0 | F12: 0 | G12: 255
A13: MI0019 - OIL SEAL 125 X 150 X 13 | B13: 40 | C13: 0 | D13: 0 | E13: 0 | F13: 0 | G13: 40
... A536: MI0711 - TYRE LASER MACHINE | B536: 0 | C536: 1 | D536: 0 | E536: 0 | F536: 0 | G536: 1
B538: 76253.375 | C538: 9153 | D538: -5 | E538: -15928.75 | F538: 113 | G538: 69585.625

Sheet JUNE25
A1: For the period from 01.06.2025 to 30.06.2025 | B1: Opening balance | C1: Purchases | D1: Inventory Write-offs | E1: Sales | F1: Credit Note | G1: Closing balance
A2: MI0001 - 4515-Wx Hendred Brake Lining | B2: 635.625 | C2: 680 | D2: 0 | E2: -257 | F2: 20 | G2: 1078.625
A3: MI0002 - MP31 | B3: 0.25 | C3: 0 | D3: 0 | E3: 0 | F3: 0 | G3: 0.25
A4: MI0003 - MP32 | B4: 2 | C4: 128 | D4: 0 | E4: -1.25 | F4: 0 | G4: 128.75
A5: MI0004 - MP36 | B5: 157.875 | C5: 0 | D5: 0 | E5: -34.25 | F5: 0 | G5: 123.625
A6: MI0005 - BC36 | B6: 29.75 | C6: 300 | D6: -0.125 | E6: -10 | F6: 0 | G6: 319.625
A7: MI0008 - 996075-K AIRBAG VOLVO O/M 1076076 | B7: 2 | C7: 0 | D7: 0 | E7: 0 | F7: 0 | G7: 2
A8: MI0009 - 994713-K AIRBAG VOLVO O/M 1076595 | B8: 13 | C8: 0 | D8: 0 | E8: -6 | F8: 0 | G8: 7
A9: MI0010 - 994913-K AIRBAG SCA 124 DIFF / 9881 | B9: 14 | C9: 0 | D9: 0 | E9: -2 | F9: 0 | G9: 12
A10: MI0011 - 999780-K AIRBAG FREIGHTLINER METAL | B10: 2 | C10: 50 | D10: 0 | E10: -1 | F10: 0 | G10: 51
A11: MI0013 - 994183-24K AIRBAG BENZ | B11: -14 | C11: 0 | D11: 0 | E11: 0 | F11: 0 | G11: -14
A12: MI0018 - BPW SPRING LONG | B12: 255 | C12: 0 | D12: 0 | E12: -2 | F12: 0 | G12: 253
A13: MI0019 - OIL SEAL 125 X 150 X 13 | B13: 40 | C13: 0 | D13: 0 | E13: -4 | F13: 0 | G13: 36
... A559: MI0732 - W01M58-8619 BPW 6 HOLE AIRBAG 37941-C | B559: 0 | C559: 10 | D559: 0 | E559: -2 | F559: 0 | G559: 8
B561: 69585.625 | C561: 23329 | D561: -22.125 | E561: -13980 | F561: 82 | G561: 78994.5

Sheet JULY25
A1: For the period from 01.07.2025 to 31.07.2025 | B1: Opening balance | C1: Purchases | D1: Inventory Write-offs | E1: Sales | F1: Credit Note | G1: Closing balance
A2: MI0001 - 4515-Wx Hendred Brake Lining | B2: 1078.625 | C2: 0 | D2: 0 | E2: -211.75 | F2: 0 | G2: 866.875
A3: MI0002 - MP31 | B3: 0.25 | C3: 0 | D3: 0 | E3: 0 | F3: 0 | G3: 0.25
A4: MI0003 - MP32 | B4: 128.75 | C4: 0 | D4: 0 | E4: -15 | F4: 0 | G4: 113.75
A5: MI0004 - MP36 | B5: 123.625 | C5: 0 | D5: 0 | E5: -26 | F5: 0 | G5: 97.625
A6: MI0005 - BC36 | B6: 319.625 | C6: 0 | D6: 0 | E6: -27.25 | F6: 0 | G6: 292.375
A7: MI0008 - 996075-K AIRBAG VOLVO O/M 1076076 | B7: 2 | C7: 0 | D7: 0 | E7: 0 | F7: 0 | G7: 2
A8: MI0009 - 994713-K AIRBAG VOLVO O/M 1076595 | B8: 7 | C8: 0 | D8: 0 | E8: -2 | F8: 0 | G8: 5
A9: MI0010 - 994913-K AIRBAG SCA 124 DIFF / 9881 | B9: 12 | C9: 0 | D9: 0 | E9: -1 | F9: 0 | G9: 11
A10: MI0011 - 999780-K AIRBAG FREIGHTLINER METAL | B10: 51 | C10: 0 | D10: 0 | E10: -11 | F10: 0 | G10: 40
A11: MI0013 - 994183-24K AIRBAG BENZ | B11: -14 | C11: 0 | D11: 0 | E11: 0 | F11: 0 | G11: -14
A12: MI0018 - BPW SPRING LONG | B12: 253 | C12: 0 | D12: 0 | E12: 0 | F12: 0 | G12: 253
A13: MI0019 - OIL SEAL 125 X 150 X 13 | B13: 36 | C13: 0 | D13: 0 | E13: -1 | F13: 0 | G13: 35
... A558: MI0738 - SOLAR LED LIGHT 1000W | B558: 0 | C558: 138 | D558: 0 | E558: -13 | F558: 0 | G558: 125
B560: 78993.5 | C560: 6214 | D560: -14 | E560: -12349.5 | F560: 4 | G560: 72848

Sheet AUG25
A1: For the period from 01.08.2025 to 31.08.2025 | B1: Opening balance | C1: Purchases | D1: Inventory Write-offs | E1: Sales | F1: Credit Note | G1: Closing balance
A2: MI0001 - 4515-Wx Hendred Brake Lining | B2: 866.875 | C2: 0 | D2: 0 | E2: -145.25 | F2: 0 | G2: 721.625
A3: MI0002 - MP31 | B3: 0.25 | C3: 0 | D3: 0 | E3: 0 | F3: 0 | G3: 0.25
A4: MI0003 - MP32 | B4: 113.75 | C4: 0 | D4: 0 | E4: -21.25 | F4: 0 | G4: 92.5
A5: MI0004 - MP36 | B5: 97.625 | C5: 0 | D5: 0 | E5: -10.625 | F5: 0 | G5: 87
A6: MI0005 - BC36 | B6: 292.375 | C6: 0 | D6: 0 | E6: -29.25 | F6: 0 | G6: 263.125
A7: MI0008 - 996075-K AIRBAG VOLVO O/M 1076076 | B7: 2 | C7: 0 | D7: 0 | E7: 0 | F7: 0 | G7: 2
A8: MI0009 - 994713-K AIRBAG VOLVO O/M 1076595 | B8: 5 | C8: 0 | D8: 0 | E8: 0 | F8: 0 | G8: 5
A9: MI0010 - 994913-K AIRBAG SCA 124 DIFF / 9881 | B9: 11 | C9: 0 | D9: 0 | E9: -2 | F9: 0 | G9: 9
A10: MI0011 - 999780-K AIRBAG FREIGHTLINER METAL | B10: 40 | C10: 0 | D10: 0 | E10: -2 | F10: 0 | G10: 38
A11: MI0013 - 994183-24K AIRBAG BENZ | B11: -14 | C11: 0 | D11: 0 | E11: 0 | F11: 0 | G11: -14
A12: MI0018 - BPW SPRING LONG | B12: 253 | C12: 0 | D12: 0 | E12: -18 | F12: 0 | G12: 235
A13: MI0019 - OIL SEAL 125 X 150 X 13 | B13: 35 | C13: 0 | D13: 0 | E13: -5 | F13: 0 | G13: 30
... A560: MI0744 - 12KW INVERTER - SLR | B560: 0 | C560: 1 | D560: 0 | E560: 0 | F560: 0 | G560: 1
B562: 72848 | C562: 27335 | D562: -12 | E562: -15673.625 | F562: 17 | G562: 84514.375

Sheet SEP25
B1: Opening balance | C1: Purchases | D1: Debit Notes | E1: Inventory Write-offs | F1: Sales | G1: Credit Note | H1: Closing balance
A2: MI0001 - 4515-Wx Hendred Brake Lining | B2: 721.625 | C2: 902 | D2: - | E2: -3 | F2: -228.25 | G2: - | H2: 1392.375
A3: MI0002 - MP31 | B3: 0.25 | C3: - | D3: - | E3: - | F3: - | G3: - | H3: 0.25
A4: MI0003 - MP32 | B4: 92.5 | C4: - | D4: - | E4: - | F4: -15.75 | G4: - | H4: 76.75
A5: MI0004 - MP36 | B5: 87 | C5: - | D5: - | E5: - | F5: -9 | G5: - | H5: 78
A6: MI0005 - BC36 | B6: 263.125 | C6: - | D6: - | E6: - | F6: -28 | G6: - | H6: 235.125
A7: MI0008 - 996075-K AIRBAG VOLVO O/M 1076076 | B7: 2 | C7: - | D7: - | E7: - | F7: - | G7: - | H7: 2
A8: MI0009 - 994713-K AIRBAG VOLVO O/M 1076595 | B8: 5 | C8: - | D8: - | E8: - | F8: - | G8: - | H8: 5
A9: MI0010 - 994913-K AIRBAG SCA 124 DIFF / 9881 | B9: 9 | C9: - | D9: - | E9: - | F9: -3 | G9: - | H9: 6
A10: MI0011 - 999780-K AIRBAG FREIGHTLINER METAL | B10: 38 | C10: - | D10: - | E10: - | F10: -9 | G10: - | H10: 29
A11: MI0013 - 994183-24K AIRBAG BENZ | B11: -14 | C11: - | D11: - | E11: - | F11: - | G11: - | H11: -14
A12: MI0018 - BPW SPRING LONG | B12: 235 | C12: - | D12: - | E12: - | F12: -1 | G12: - | H12: 234
A13: MI0019 - OIL SEAL 125 X 150 X 13 | B13: 30 | C13: - | D13: - | E13: - | F13: -1 | G13: - | H13: 29
A14: MI0021 - H24W05 | B14: 7 | C14: - | D14: - | E14: - | F14: - | G14: - | H14: 7
A15: MI00218 - HENDRED ROLLER BIG | B15: -109 | C15: - | D15: - | E15: - | F15: -12 | G15: - | H15: -121
A16: MI0027 - FILTER 8193841 WATER SEPERATOR | B16: -6 | C16: - | D16: - | E16: - | F16: - | G16: - | H16: -6
A17: MI0029 - BOLT WITH NUT SCANIA REAR | B17: 7 | C17: - | D17: - | E17: - | F17: - | G17: - | H17: 7
A18: MI0035 - 0683578 WATER PUMP DAF | B18: 3 | C18: - | D18: - | E18: - | F18: -1 | G18: - | H18: 2
A19: MI0043 - L2320 PRESSURE PLATE SCANIA | B19: 1 | C19: - | D19: - | E19: - | F19: - | G19: - | H19: 1
A20: MI0045 - 4801030160 VALVE BENZ | B20: 1 | C20: - | D20: - | E20: - | F20: - | G20: - | H20: 1
A21: MI0047 - RL3530EA23-E BRAKE BOOSTER 24/30 TRAILER | B21: 7 | C21: - | D21: - | E21: - | F21: -5 | G21: - | H21: 2
A22: MI0048 - HTP-NFH002R-R HEAD LAMP LENS RIGHT VOLVO | B22: 7 | C22: - | D22: - | E22: - | F22: - | G22: - | H22: 7
A23: MI0049 - HTP-NFH002R-L HEAD LAMP LENS LEFT VOLVO | B23: 7 | C23: - | D23: - | E23: - | F23: - | G23: - | H23: 7
A24: MI0052 - SV41 BRAKE LINING SCA | B24: 12 | C24: - | D24: - | E24: - | F24: - | G24: - | H24: 12
A25: MI0053 - SV42 BRAKE LINING SCANIA | B25: 89.75 | C25: - | D25: - | E25: - | F25: - | G25: - | H25: 89.75
A26: MI0054 - VL87 BRAKE LINING VOLVO | B26: 36 | C26: - | D26: - | E26: - | F26: -5.25 | G26: - | H26: 30.75
A27: MI0055 - VL88 BRAKE LINING VOLVO | B27: 107.5 | C27: - | D27: - | E27: - | F27: -5 | G27: - | H27: 102.5
A28: MI0056 - VL89 BRAKE LINING VOLVO | B28: 0.5 | C28: - | D28: - | E28: - | F28: - | G28: - | H28: 0.5
A29: MI0057 - BC37 BRAKE LINING BPW 8" | B29: 308 | C29: 468 | D29: - | E29: - | F29: -23 | G29: - | H29: 753
A30: MI0059 - RIVETING MACHINE | B30: 5 | C30: - | D30: - | E30: - | F30: - | G30: - | H30: 5
A31: MI0060 - W01M586364 AIRBAG 5813K | B31: 173 | C31: - | D31: - | E31: - | F31: -60 | G31: - | H31: 113
A32: MI0061 - WVA29124 BRAKE PAD ROR | B32: 1 | C32: - | D32: - | E32: - | F32: - | G32: - | H32: 1
A33: MI0064 - BRAKE SHOE BC36 | B33: 19 | C33: - | D33: - | E33: - | F33: -4 | G33: - | H33: 15
A34: MI0065 - 4515 BRAKE SHOE COMP OR HENDRED | B34: -49 | C34: - | D34: - | E34: - | F34: -2 | G34: - | H34: -51
A35: MI0066 - W01-M58-8966 | B35: 85 | C35: - | D35: - | E35: - | F35: -35 | G35: - | H35: 50
A36: MI0067 - HENDRED BRAKE SHOE SPRING LONG | B36: -176 | C36: - | D36: - | E36: - | F36: -29 | G36: - | H36: -205
A37: MI0068 - HENDRED BRAKE SHOE SPRING SHORT | B37: -278 | C37: - | D37: - | E37: - | F37: -79 | G37: - | H37: -357
A38: MI0069 - BRAKE SHOE ROLLER BPW | B38: -6 | C38: - | D38: - | E38: - | F38: - | G38: - | H38: -6
A39: MI0070 - BRAKE SHOE ROLLER LOCK | B39: -306 | C39: - | D39: - | E39: - | F39: - | G39: - | H39: -306
A40: MI0073 - 4707 BRAKE LINING | B40: 191.5 | C40: - | D40: - | E40: - | F40: -2 | G40: - | H40: 189.5
...

Sheet OCT25
A1: 1st oct 2025 to 31 oct 2025 | B1: Opening balance | C1: Purchases | D1: Inventory Write-offs | E1: Sales | F1: Credit Note | G1: Closing balance
A2: MI0001 - 4515-Wx Hendred Brake Lining | B2: 1392.38 | C2: - | D2: - | E2: -331.25 | F2: - | G2: 1061.13
A3: MI0002 - MP31 | B3: 0.25 | C3: - | D3: - | E3: - | F3: - | G3: 0.25
A4: MI0003 - MP32 | B4: 76.75 | C4: - | D4: - | E4: -8.5 | F4: - | G4: 68.25
A5: MI0004 - MP36 | B5: 78 | C5: 4.5 | D5: - | E5: -11 | F5: - | G5: 71.5
A6: MI0005 - BC36 | B6: 235.125 | C6: - | D6: - | E6: -45.5 | F6: - | G6: 189.625
A7: MI0008 - 996075-K AIRBAG VOLVO O/M 1076076 | B7: 2 | C7: - | D7: - | E7: - | F7: - | G7: 2
A8: MI0009 - 994713-K AIRBAG VOLVO O/M 1076595 | B8: 5 | C8: - | D8: - | E8: - | F8: - | G8: 5
A9: MI0010 - 994913-K AIRBAG SCA 124 DIFF / 9881 | B9: 6 | C9: 1 | D9: - | E9: -3 | F9: - | G9: 4
A10: MI0011 - 999780-K AIRBAG FREIGHTLINER METAL | B10: 29 | C10: - | D10: - | E10: -1 | F10: - | G10: 28
A11: MI0013 - 994183-24K AIRBAG BENZ | B11: -14 | C11: - | D11: - | E11: - | F11: - | G11: -14
A12: MI0018 - BPW SPRING LONG | B12: 234 | C12: 200 | D12: - | E12: -7 | F12: - | G12: 427
A13: MI0019 - OIL SEAL 125 X 150 X 13 | B13: 29 | C13: - | D13: - | E13: -6 | F13: - | G13: 23
A14: MI0021 - H24W05 | B14: 7 | C14: - | D14: - | E14: - | F14: - | G14: 7
A15: MI00218 - HENDRED ROLLER BIG | B15: -121 | C15: - | D15: - | E15: -31 | F15: - | G15: -152
A16: MI0027 - FILTER 8193841 WATER SEPERATOR | B16: -6 | C16: - | D16: - | E16: - | F16: - | G16: -6
A17: MI0029 - BOLT WITH NUT SCANIA REAR | B17: 7 | C17: - | D17: - | E17: - | F17: - | G17: 7
A18: MI0035 - 0683578 WATER PUMP DAF | B18: 2 | C18: - | D18: - | E18: - | F18: - | G18: 2
A19: MI0043 - L2320 PRESSURE PLATE SCANIA | B19: 1 | C19: - | D19: - | E19: - | F19: - | G19: 1
A20: MI0045 - 4801030160 VALVE BENZ | B20: 1 | C20: - | D20: - | E20: - | F20: - | G20: 1
A21: MI0047 - RL3530EA23-E BRAKE BOOSTER 24/30 TRAILER | B21: 2 | C21: 120 | D21: -1 | E21: -121 | F21: 1 | G21: 1
A22: MI0048 - HTP-NFH002R-R HEAD LAMP LENS RIGHT VOLVO | B22: 7 | C22: - | D22: - | E22: - | F22: - | G22: 7
A23: MI0049 - HTP-NFH002R-L HEAD LAMP LENS LEFT VOLVO | B23: 7 | C23: - | D23: - | E23: - | F23: - | G23: 7
A24: MI0052 - SV41 BRAKE LINING SCA | B24: 12 | C24: - | D24: - | E24: - | F24: - | G24: 12
A25: MI0053 - SV42 BRAKE LINING SCANIA | B25: 89.75 | C25: - | D25: - | E25: - | F25: - | G25: 89.75
A26: MI0054 - VL87 BRAKE LINING VOLVO | B26: 30.75 | C26: - | D26: - | E26: -4 | F26: - | G26: 26.75
A27: MI0055 - VL88 BRAKE LINING VOLVO | B27: 102.5 | C27: - | D27: - | E27: -4 | F27: - | G27: 98.5
A28: MI0056 - VL89 BRAKE LINING VOLVO | B28: 0.5 | C28: - | D28: - | E28: - | F28: - | G28: 0.5
A29: MI0057 - BC37 BRAKE LINING BPW 8" | B29: 753 | C29: - | D29: - | E29: -125.5 | F29: - | G29: 627.5
A30: MI0059 - RIVETING MACHINE | B30: 5 | C30: - | D30: - | E30: - | F30: - | G30: 5
A31: MI0060 - W01M586364 AIRBAG 5813K | B31: 113 | C31: 8 | D31: - | E31: -24 | F31: - | G31: 97
A32: MI0061 - WVA29124 BRAKE PAD ROR | B32: 1 | C32: - | D32: - | E32: - | F32: - | G32: 1
A33: MI0064 - BRAKE SHOE BC36 | B33: 15 | C33: 36 | D33: - | E33: -2 | F33: - | G33: 49
A34: MI0065 - 4515 BRAKE SHOE COMP OR HENDRED | B34: -51 | C34: 150 | D34: - | E34: -34 | F34: - | G34: 65
A35: MI0066 - W01-M58-8966 | B35: 50 | C35: 15 | D35: - | E35: -38 | F35: - | G35: 27
A36: MI0067 - HENDRED BRAKE SHOE SPRING LONG | B36: -205 | C36: 500 | D36: - | E36: -8 | F36: - | G36: 287
A37: MI0068 - HENDRED BRAKE SHOE SPRING SHORT | B37: -357 | C37: 1000 | D37: - | E37: -93 | F37: - | G37: 550
A38: MI0069 - BRAKE SHOE ROLLER BPW | B38: -6 | C38: - | D38: - | E38: - | F38: - | G38: -6
A39: MI0070 - BRAKE SHOE ROLLER LOCK | B39: -306 | C39: - | D39: - | E39: - | F39: - | G39: -306
A40: MI0073 - 4707 BRAKE LINING | B40: 189.5 | C40: - | D40: - | E40: -3 | F40: - | G40: 186.5
...

Sheet NOV25
C1: Opening balance | D1: Purchases | E1: Inventory Write-offs | F1: Sales | G1: Credit Note | H1: Journal Entries | I1: Closing balance
A2: 0 | B2: MI0001 - 4515-Wx Hendred Brake Lining | C2: 1061.125 | D2: - | E2: -0.25 | F2: -234.75 | G2: 12 | H2: - | I2: 838.125
A3: 0 | B3: MI0002 - MP31 | C3: 0.25 | D3: - | E3: - | F3: - | G3: - | H3: - | I3: 0.25
A4: 0 | B4: MI0003 - MP32 | C4: 68.25 | D4: - | E4: - | F4: -10.5 | G4: - | H4: - | I4: 57.75
A5: 0 | B5: MI0004 - MP36 | C5: 71.5 | D5: 3.125 | E5: - | F5: -13 | G5: - | H5: - | I5: 61.625
A6: 0 | B6: MI0005 - BC36 | C6: 189.625 | D6: - | E6: -0.25 | F6: -58.75 | G6: - | H6: - | I6: 130.625
A7: 0 | B7: MI0008 - 996075-K AIRBAG VOLVO O/M 1076076 | C7: 2 | D7: - | E7: - | F7: - | G7: - | H7: - | I7: 2
A8: 0 | B8: MI0009 - 994713-K AIRBAG VOLVO O/M 1076595 | C8: 5 | D8: - | E8: - | F8: - | G8: - | H8: - | I8: 5
A9: 0 | B9: MI0010 - 994913-K AIRBAG SCA 124 DIFF / 9881 | C9: 4 | D9: - | E9: - | F9: -3 | G9: - | H9: - | I9: 1
A10: 0 | B10: MI0011 - 999780-K AIRBAG FREIGHTLINER METAL | C10: 28 | D10: 50 | E10: - | F10: -8 | G10: - | H10: - | I10: 70
A11: 0 | B11: MI0013 - 994183-24K AIRBAG BENZ | C11: -14 | D11: - | E11: - | F11: - | G11: - | H11: - | I11: -14
A12: 0 | B12: MI0018 - BPW SPRING LONG | C12: 427 | D12: - | E12: - | F12: -26 | G12: - | H12: - | I12: 401
A13: 0 | B13: MI0019 - OIL SEAL 125 X 150 X 13 | C13: 23 | D13: - | E13: - | F13: - | G13: - | H13: - | I13: 23
A14: 0 | B14: MI0021 - H24W05 | C14: 7 | D14: - | E14: - | F14: - | G14: - | H14: - | I14: 7
A15: 0 | B15: MI00218 - HENDRED ROLLER BIG | C15: -152 | D15: - | E15: - | F15: - | G15: - | H15: - | I15: -152
A16: 0 | B16: MI0027 - FILTER 8193841 WATER SEPERATOR | C16: -6 | D16: - | E16: - | F16: - | G16: - | H16: - | I16: -6
A17: 0 | B17: MI0029 - BOLT WITH NUT SCANIA REAR | C17: 7 | D17: - | E17: - | F17: - | G17: - | H17: - | I17: 7
A18: 0 | B18: MI0035 - 0683578 WATER PUMP DAF | C18: 2 | D18: - | E18: - | F18: - | G18: - | H18: - | I18: 2
A19: 0 | B19: MI0043 - L2320 PRESSURE PLATE SCANIA | C19: 1 | D19: - | E19: - | F19: - | G19: - | H19: - | I19: 1
A20: 0 | B20: MI0045 - 4801030160 VALVE BENZ | C20: 1 | D20: - | E20: - | F20: - | G20: - | H20: - | I20: 1
A21: 0 | B21: MI0047 - RL3530EA23-E BRAKE BOOSTER 24/30 TRAILER | C21: 1 | D21: 300 | E21: - | F21: -34 | G21: 8 | H21: - | I21: 275
A22: 0 | B22: MI0048 - HTP-NFH002R-R HEAD LAMP LENS RIGHT VOLVO | C22: 7 | D22: - | E22: - | F22: - | G22: - | H22: - | I22: 7
A23: 0 | B23: MI0049 - HTP-NFH002R-L HEAD LAMP LENS LEFT VOLVO | C23: 7 | D23: - | E23: - | F23: - | G23: - | H23: - | I23: 7
A24: 0 | B24: MI0052 - SV41 BRAKE LINING SCA | C24: 12 | D24: - | E24: - | F24: - | G24: - | H24: - | I24: 12
A25: 0 | B25: MI0053 - SV42 BRAKE LINING SCANIA | C25: 89.75 | D25: - | E25: - | F25: - | G25: - | H25: - | I25: 89.75
A26: 0 | B26: MI0054 - VL87 BRAKE LINING VOLVO | C26: 26.75 | D26: - | E26: - | F26: -3.75 | G26: - | H26: - | I26: 23
A27: 0 | B27: MI0055 - VL88 BRAKE LINING VOLVO | C27: 98.5 | D27: - | E27: - | F27: -11.5 | G27: - | H27: - | I27: 87
A28: 0 | B28: MI0056 - VL89 BRAKE LINING VOLVO | C28: 0.5 | D28: - | E28: - | F28: - | G28: - | H28: - | I28: 0.5
A29: 0 | B29: MI0057 - BC37 BRAKE LINING BPW 8" | C29: 627.5 | D29: - | E29: - | F29: -58.25 | G29: - | H29: - | I29: 569.25
A30: 0 | B30: MI0059 - RIVETING MACHINE | C30: 5 | D30: - | E30: - | F30: - | G30: - | H30: - | I30: 5
A31: 0 | B31: MI0060 - W01M586364 AIRBAG 5813K | C31: 97 | D31: 180 | E31: - | F31: -24 | G31: 3 | H31: - | I31: 256
A32: 0 | B32: MI0061 - WVA29124 BRAKE PAD ROR | C32: 1 | D32: - | E32: - | F32: - | G32: - | H32: - | I32: 1
A33: 0 | B33: MI0064 - BRAKE SHOE BC36 | C33: 49 | D33: - | E33: - | F33: -1 | G33: - | H33: - | I33: 48
A34: 0 | B34: MI0065 - 4515 BRAKE SHOE COMP OR HENDRED | C34: 65 | D34: 51 | E34: - | F34: -49 | G34: 10 | H34: - | I34: 77
A35: 0 | B35: MI0066 - W01-M58-8966 | C35: 27 | D35: 120 | E35: - | F35: -33 | G35: - | H35: - | I35: 114
A36: 0 | B36: MI0067 - HENDRED BRAKE SHOE SPRING LONG | C36: 287 | D36: 400 | E36: - | F36: -65 | G36: - | H36: - | I36: 622
A37: 0 | B37: MI0068 - HENDRED BRAKE SHOE SPRING SHORT | C37: 550 | D37: 500 | E37: - | F37: -106 | G37: - | H37: - | I37: 944
A38: 0 | B38: MI0069 - BRAKE SHOE ROLLER BPW | C38: -6 | D38: - | E38: - | F38: - | G38: - | H38: - | I38: -6
A39: 0 | B39: MI0070 - BRAKE SHOE ROLLER LOCK | C39: -306 | D39: - | E39: - | F39: -8 | G39: - | H39: - | I39: -314
A40: 0 | B40: MI0073 - 4707 BRAKE LINING | C40: 186.5 | D40: - | E40: - | F40: -7.25 | G40: - | H40: - | I40: 179.25
...

Sheet DEC25
B1: Opening balance | C1: Purchases | D1: Inventory Write-offs | E1: Sales | F1: Credit Note | G1: Journal Entries | H1: Closing balance
A2: MI0001 - 4515-Wx Hendred Brake Lining | B2: 838.125 | C2: 1360 | D2: - | E2: -256 | F2: 4.5 | G2: - | H2: 1946.63
A3: MI0002 - MP31 | B3: 0.25 | C3: - | D3: - | E3: - | F3: - | G3: - | H3: 0.25
A4: MI0003 - MP32 | B4: 57.75 | C4: - | D4: - | E4: -8 | F4: - | G4: - | H4: 49.75
A5: MI0004 - MP36 | B5: 61.625 | C5: 1.5 | D5: - | E5: -7.5 | F5: - | G5: - | H5: 55.625
A6: MI0005 - BC36 | B6: 130.625 | C6: - | D6: - | E6: -25.5 | F6: - | G6: - | H6: 105.125
A7: MI0008 - 996075-K AIRBAG VOLVO O/M 1076076 | B7: 2 | C7: - | D7: - | E7: - | F7: - | G7: - | H7: 2
A8: MI0009 - 994713-K AIRBAG VOLVO O/M 1076595 | B8: 5 | C8: - | D8: - | E8: - | F8: - | G8: - | H8: 5
A9: MI0010 - 994913-K AIRBAG SCA 124 DIFF / 9881 | B9: 1 | C9: 5 | D9: - | E9: -2 | F9: - | G9: - | H9: 4
A10: MI0011 - 999780-K AIRBAG FREIGHTLINER METAL | B10: 70 | C10: - | D10: - | E10: -5 | F10: - | G10: - | H10: 65
A11: MI0013 - 994183-24K AIRBAG BENZ | B11: -14 | C11: - | D11: - | E11: - | F11: - | G11: - | H11: -14
A12: MI0018 - BPW SPRING LONG | B12: 401 | C12: - | D12: - | E12: -5 | F12: - | G12: - | H12: 396
A13: MI0019 - OIL SEAL 125 X 150 X 13 | B13: 23 | C13: - | D13: - | E13: -1 | F13: - | G13: - | H13: 22
A14: MI0021 - H24W05 | B14: 7 | C14: - | D14: - | E14: - | F14: - | G14: - | H14: 7
A15: MI00218 - HENDRED ROLLER BIG | B15: -152 | C15: - | D15: - | E15: -8 | F15: - | G15: - | H15: -160
A16: MI0027 - FILTER 8193841 WATER SEPERATOR | B16: -6 | C16: - | D16: - | E16: - | F16: - | G16: - | H16: -6
A17: MI0029 - BOLT WITH NUT SCANIA REAR | B17: 7 | C17: - | D17: - | E17: - | F17: - | G17: - | H17: 7
A18: MI0035 - 0683578 WATER PUMP DAF | B18: 2 | C18: - | D18: - | E18: - | F18: - | G18: - | H18: 2
A19: MI0043 - L2320 PRESSURE PLATE SCANIA | B19: 1 | C19: - | D19: - | E19: - | F19: - | G19: - | H19: 1
A20: MI0045 - 4801030160 VALVE BENZ | B20: 1 | C20: - | D20: - | E20: - | F20: - | G20: - | H20: 1
A21: MI0047 - RL3530EA23-E BRAKE BOOSTER 24/30 TRAILER | B21: 275 | C21: - | D21: - | E21: -101 | F21: - | G21: - | H21: 174
A22: MI0048 - HTP-NFH002R-R HEAD LAMP LENS RIGHT VOLVO | B22: 7 | C22: - | D22: - | E22: - | F22: - | G22: - | H22: 7
A23: MI0049 - HTP-NFH002R-L HEAD LAMP LENS LEFT VOLVO | B23: 7 | C23: - | D23: - | E23: - | F23: - | G23: - | H23: 7
A24: MI0052 - SV41 BRAKE LINING SCA | B24: 12 | C24: - | D24: - | E24: -2 | F24: - | G24: - | H24: 10
A25: MI0053 - SV42 BRAKE LINING SCANIA | B25: 89.75 | C25: - | D25: - | E25: - | F25: - | G25: - | H25: 89.75
A26: MI0054 - VL87 BRAKE LINING VOLVO | B26: 23 | C26: - | D26: - | E26: -5 | F26: - | G26: - | H26: 18
A27: MI0055 - VL88 BRAKE LINING VOLVO | B27: 87 | C27: - | D27: - | E27: -15.75 | F27: - | G27: - | H27: 71.25
A28: MI0056 - VL89 BRAKE LINING VOLVO | B28: 0.5 | C28: - | D28: - | E28: - | F28: - | G28: - | H28: 0.5
A29: MI0057 - BC37 BRAKE LINING BPW 8" | B29: 569.25 | C29: 442 | D29: - | E29: -20 | F29: - | G29: - | H29: 991.25
A30: MI0059 - RIVETING MACHINE | B30: 6 | C30: - | D30: - | E30: - | F30: - | G30: - | H30: 6
A31: MI0060 - W01M586364 AIRBAG 5813K | B31: 256 | C31: 100 | D31: - | E31: -49 | F31: - | G31: - | H31: 307
A32: MI0061 - WVA29124 BRAKE PAD ROR | B32: 1 | C32: - | D32: - | E32: - | F32: - | G32: - | H32: 1
A33: MI0064 - BRAKE SHOE BC36 | B33: 48 | C33: - | D33: -2 | E33: - | F33: - | G33: - | H33: 46
A34: MI0065 - 4515 BRAKE SHOE COMP OR HENDRED | B34: 77 | C34: 100 | D34: - | E34: -27 | F34: - | G34: - | H34: 150
A35: MI0066 - W01-M58-8966 | B35: 114 | C35: 100 | D35: - | E35: -53 | F35: - | G35: - | H35: 161
A36: MI0067 - HENDRED BRAKE SHOE SPRING LONG | B36: 622 | C36: 20 | D36: - | E36: -238 | F36: - | G36: - | H36: 404
A37: MI0068 - HENDRED BRAKE SHOE SPRING SHORT | B37: 944 | C37: - | D37: - | E37: -330 | F37: - | G37: - | H37: 614
A38: MI0069 - BRAKE SHOE ROLLER BPW | B38: -6 | C38: - | D38: - | E38: - | F38: - | G38: - | H38: -6
A39: MI0070 - BRAKE SHOE ROLLER LOCK | B39: -314 | C39: - | D39: - | E39: - | F39: - | G39: - | H39: -314
A40: MI0073 - 4707 BRAKE LINING | B40: 179.25 | C40: - | D40: - | E40: -2.5 | F40: 0.5 | G40: - | H40: 177.25
...

Sheet JAN26
B1: Opening balance | C1: Purchases | D1: Debit Notes | E1: Inventory Write-offs | F1: Sales | G1: Credit Note | H1: Closing balance
A2: MI0001 - 4515-Wx Hendred Brake Lining | B2: 1946.625 | C2: - | D2: - | E2: - | F2: -349 | G2: - | H2: 1597.625
A3: MI0002 - MP31 | B3: 0.25 | C3: - | D3: - | E3: - | F3: - | G3: - | H3: 0.25
A4: MI0003 - MP32 | B4: 49.75 | C4: - | D4: - | E4: - | F4: -19 | G4: - | H4: 30.75
A5: MI0004 - MP36 | B5: 55.625 | C5: 3 | D5: - | E5: - | F5: -15.125 | G5: - | H5: 43.5
A6: MI0005 - BC36 | B6: 105.125 | C6: - | D6: - | E6: -2 | F6: -39.75 | G6: - | H6: 63.375
A7: MI0008 - 996075-K AIRBAG VOLVO O/M 1076076 | B7: 2 | C7: - | D7: - | E7: - | F7: - | G7: - | H7: 2
A8: MI0009 - 994713-K AIRBAG VOLVO O/M 1076595 | B8: 5 | C8: - | D8: - | E8: - | F8: - | G8: - | H8: 5
A9: MI0010 - 994913-K AIRBAG SCA 124 DIFF / 9881 | B9: 4 | C9: - | D9: - | E9: - | F9: -2 | G9: - | H9: 2
A10: MI0011 - 999780-K AIRBAG FREIGHTLINER METAL | B10: 65 | C10: - | D10: - | E10: - | F10: -1 | G10: - | H10: 64
A11: MI00117 - Z SPRING BPW | B11: - | C11: 25 | D11: - | E11: - | F11: - | G11: - | H11: 25
A12: MI0013 - 994183-24K AIRBAG BENZ | B12: -14 | C12: 14 | D12: - | E12: - | F12: - | G12: - | H12: -
A13: MI0018 - BPW SPRING LONG | B13: 396 | C13: - | D13: - | E13: - | F13: -11 | G13: - | H13: 385
A14: MI0019 - OIL SEAL 125 X 150 X 13 | B14: 22 | C14: - | D14: - | E14: - | F14: - | G14: - | H14: 22
A15: MI0021 - H24W05 | B15: 7 | C15: - | D15: - | E15: - | F15: - | G15: - | H15: 7
A16: MI00218 - HENDRED ROLLER BIG | B16: -160 | C16: 362 | D16: - | E16: - | F16: -41 | G16: - | H16: 161
A17: MI0027 - FILTER 8193841 WATER SEPERATOR | B17: -6 | C17: - | D17: - | E17: - | F17: - | G17: - | H17: -6
A18: MI0029 - BOLT WITH NUT SCANIA REAR | B18: 7 | C18: - | D18: - | E18: - | F18: - | G18: - | H18: 7
A19: MI0035 - 0683578 WATER PUMP DAF | B19: 2 | C19: - | D19: - | E19: - | F19: -1 | G19: - | H19: 1
A20: MI0043 - L2320 PRESSURE PLATE SCANIA | B20: 1 | C20: - | D20: - | E20: - | F20: - | G20: - | H20: 1
A21: MI0045 - 4801030160 VALVE BENZ | B21: 1 | C21: - | D21: - | E21: - | F21: - | G21: - | H21: 1
A22: MI0047 - RL3530EA23-E BRAKE BOOSTER 24/30 TRAILER | B22: 174 | C22: 350 | D22: - | E22: - | F22: -96 | G22: - | H22: 428
A23: MI0048 - HTP-NFH002R-R HEAD LAMP LENS RIGHT VOLVO | B23: 7 | C23: - | D23: - | E23: - | F23: - | G23: - | H23: 7
A24: MI0049 - HTP-NFH002R-L HEAD LAMP LENS LEFT VOLVO | B24: 7 | C24: - | D24: - | E24: - | F24: - | G24: - | H24: 7
A25: MI0052 - SV41 BRAKE LINING SCA | B25: 10 | C25: - | D25: - | E25: - | F25: - | G25: - | H25: 10
A26: MI0053 - SV42 BRAKE LINING SCANIA | B26: 89.75 | C26: - | D26: - | E26: - | F26: -1 | G26: - | H26: 88.75
A27: MI0054 - VL87 BRAKE LINING VOLVO | B27: 18 | C27: - | D27: - | E27: - | F27: -1 | G27: - | H27: 17
A28: MI0055 - VL88 BRAKE LINING VOLVO | B28: 71.25 | C28: - | D28: - | E28: - | F28: -14.25 | G28: - | H28: 57
A29: MI0056 - VL89 BRAKE LINING VOLVO | B29: 0.5 | C29: - | D29: - | E29: - | F29: - | G29: - | H29: 0.5
A30: MI0057 - BC37 BRAKE LINING BPW 8" | B30: 991.25 | C30: - | D30: - | E30: - | F30: -53.25 | G30: - | H30: 938
A31: MI0059 - RIVETING MACHINE | B31: 6 | C31: - | D31: - | E31: - | F31: - | G31: - | H31: 6
A32: MI0060 - W01M586364 AIRBAG 5813K | B32: 307 | C32: - | D32: - | E32: - | F32: -20 | G32: - | H32: 287
A33: MI0061 - WVA29124 BRAKE PAD ROR | B33: 1 | C33: - | D33: - | E33: - | F33: - | G33: - | H33: 1
A34: MI0064 - BRAKE SHOE BC36 | B34: 46 | C34: - | D34: - | E34: - | F34: - | G34: - | H34: 46
A35: MI0065 - 4515 BRAKE SHOE COMP OR HENDRED | B35: 150 | C35: - | D35: - | E35: - | F35: -47 | G35: - | H35: 103
A36: MI0066 - W01-M58-8966 | B36: 161 | C36: - | D36: - | E36: - | F36: -40 | G36: - | H36: 121
A37: MI0067 - HENDRED BRAKE SHOE SPRING LONG | B37: 404 | C37: 981 | D37: - | E37: - | F37: -177 | G37: - | H37: 1208
A38: MI0068 - HENDRED BRAKE SHOE SPRING SHORT | B38: 614 | C38: 1362 | D38: - | E38: - | F38: -331 | G38: - | H38: 1645
A39: MI0069 - BRAKE SHOE ROLLER BPW | B39: -6 | C39: - | D39: - | E39: - | F39: - | G39: - | H39: -6
A40: MI0070 - BRAKE SHOE ROLLER LOCK | B40: -314 | C40: 362 | D40: - | E40: - | F40: - | G40: - | H40: 48
...

Sheet AVE
A1: CAT | B1: ITEMS | C1: AVERAGE | D1: 44774 | E1: 44805 | F1: 44835 | G1: 44866 | H1: 44896 | I1: 44927 | J1: 44958 | K1: 44986 | L1: 45017 | M1: 45047 | N1: 45078 | O1: 45108 | P1: 45139 | Q1: 45170 | R1: 45200 | S1: 45231 | T1: 45261 | U1: 45292 | V1: 45323 | W1: 45352 | X1: 45383 | Y1: 45413 | Z1: 45444 | AA1: 45474 | AB1: 45505 | AC1: 45536 | AD1: 45566 | AE1: 45597 | AF1: 45627 | AG1: 45658 | AH1: 45689 | AI1: 45717 | AJ1: 45748 | AK1: 45778 | AL1: 45833 | AM1: 45863 | AN1: 45894 | AO1: 45925 | AP1: 45955 | AQ1: 45986 | AR1: 46016 | AS1: JAN
A2: GWI | B2: MI0001 - 4515-Wx Hendred Brake Lining | C2: =-AVERAGE(AL2:AV2) -> 251.65625 | D2: -234.75 | E2: -208.25 | F2: -213.25 | G2: -112 | H2: -127.5 | I2: -224.5 | J2: -237.25 | K2: -254.25 | L2: -119 | M2: -153.25 | N2: -203 | O2: -121.75 | P2: -205.75 | Q2: -139.25 | R2: -158 | S2: -187.25 | T2: -215.25 | U2: -194.25 | V2: -257 | W2: -176.75 | X2: -216.75 | Y2: -187.5 | Z2: -137.25 | AA2: -129.25 | AB2: -211.75 | AC2: -132.75 | AD2: =VLOOKUP(B2,'OCT24'!$A$1:H1173,6,0) -> -188.5 | AE2: =VLOOKUP(B2,'NOV24'!$A$1:H558,6,0) -> -228.75 | AF2: =VLOOKUP(B2,'DEC24'!$A$1:$H$914,5,0) -> -169.5 | AG2: =VLOOKUP(B2,'JAN25'!$A$1:G629,5,0) -> -189.75 | AH2: =VLOOKUP(B2,'FEB25'!A$1:G1063,5,0) -> -220 | AI2: =VLOOKUP(B2,'MAR25'!$A$1:G896,5,0) -> -272 | AJ2: =VLOOKUP(B2,'APR25'!$A$1:G525,5,0) -> -245.25 | AK2: =VLOOKUP(B2,'MAY25'!$A$1:G918,5,0) -> -257.25 | AL2: =VLOOKUP(B2,JUNE25!$A$1:G621,5,0) -> -257 | AM2: =VLOOKUP(B2, JULY25!$A$1:$E$544, 5, FALSE) -> -211.75 | AN2: =VLOOKUP(B2, 'AUG25'!$A$1:$E$540, 5, FALSE) -> -145.25 | AO2: =VLOOKUP(B2, 'SEP25'!$A$1:$F$520, 6, FALSE) -> -228.25 | AP2: =VLOOKUP(B2, 'OCT25'!$A$1:$F$520, 5, FALSE) -> -331.25 | AQ2: =VLOOKUP(B2, 'NOV25'!$B$1:$I$616, 5, FALSE) -> -234.75 | AR2: =VLOOKUP(B2, 'DEC25'!$A$1:$I$611, 5, FALSE) -> -256 | AS2: =VLOOKUP(B2, 'JAN26'!$A$1:$I$607, 6, FALSE) -> -349
A3: GWI | B3: MI0002 - MP31 | C3: =-AVERAGE(AL3:AV3) -> 0 | D3: 0 | E3: 0 | F3: 0 | G3: 0 | H3: 0 | I3: -1 | J3: -1 | K3: 0 | L3: 0 | M3: 0 | N3: 0 | O3: 0 | P3: 0 | Q3: 0 | R3: 0 | S3: 0 | T3: 0 | U3: 0 | V3: 0 | W3: 0 | X3: 0 | Y3: 0 | Z3: 0 | AA3: 0 | AB3: 0 | AC3: 0 | AD3: =VLOOKUP(B3,'OCT24'!$A$1:H1174,6,0) -> 0 | AE3: =VLOOKUP(B3,'NOV24'!$A$1:H559,6,0) -> 0 | AF3: =VLOOKUP(B3,'DEC24'!$A$1:$H$914,5,0) -> 0 | AG3: =VLOOKUP(B3,'JAN25'!$A$1:G630,5,0) -> 0 | AH3: =VLOOKUP(B3,'FEB25'!A$1:G1064,5,0) -> 0 | AI3: =VLOOKUP(B3,'MAR25'!$A$1:G897,5,0) -> 0 | AJ3: =VLOOKUP(B3,'APR25'!$A$1:G526,5,0) -> 0 | AK3: =VLOOKUP(B3,'MAY25'!$A$1:G919,5,0) -> 0 | AL3: =VLOOKUP(B3,JUNE25!$A$1:G622,5,0) -> 0 | AM3: =VLOOKUP(B3, JULY25!$A$1:$E$544, 5, FALSE) -> 0 | AN3: =VLOOKUP(B3, 'AUG25'!$A$1:$E$540, 5, FALSE) -> 0 | AO3: =VLOOKUP(B3, 'SEP25'!$A$1:$F$520, 6, FALSE) -> - | AP3: =VLOOKUP(B3, 'OCT25'!$A$1:$F$520, 5, FALSE) -> - | AQ3: =VLOOKUP(B3, 'NOV25'!$B$1:$I$616, 5, FALSE) -> - | AR3: =VLOOKUP(B3, 'DEC25'!$A$1:$I$611, 5, FALSE) -> - | AS3: =VLOOKUP(B3, 'JAN26'!$A$1:$I$607, 6, FALSE) -> -
A4: GWI | B4: MI0003 - MP32 | C4: =-AVERAGE(AL4:AV4) -> 12.40625 | D4: 0 | E4: 0 | F4: 0 | G4: 0 | H4: 0 | I4: 0 | J4: 0 | K4: 0 | L4: 0 | M4: 0 | N4: 0 | O4: 0 | P4: 0 | Q4: 0 | R4: 0 | S4: -2 | T4: 0 | U4: 0 | V4: -2 | W4: -14 | X4: -8 | Y4: -9 | Z4: 0 | AA4: -3 | AB4: -4 | AC4: -10 | AD4: =VLOOKUP(B4,'OCT24'!$A$1:H1175,6,0) -> -6 | AE4: =VLOOKUP(B4,'NOV24'!$A$1:H560,6,0) -> -12 | AF4: =VLOOKUP(B4,'DEC24'!$A$1:$H$914,5,0) -> -27.75 | AG4: =VLOOKUP(B4,'JAN25'!$A$1:G631,5,0) -> -5 | AH4: =VLOOKUP(B4,'FEB25'!A$1:G1065,5,0) -> -11.25 | AI4: =VLOOKUP(B4,'MAR25'!$A$1:G898,5,0) -> -6.5 | AJ4: =VLOOKUP(B4,'APR25'!$A$1:G527,5,0) -> -5 | AK4: =VLOOKUP(B4,'MAY25'!$A$1:G920,5,0) -> -8 | AL4: =VLOOKUP(B4,JUNE25!$A$1:G623,5,0) -> -1.25 | AM4: =VLOOKUP(B4, JULY25!$A$1:$E$544, 5, FALSE) -> -15 | AN4: =VLOOKUP(B4, 'AUG25'!$A$1:$E$540, 5, FALSE) -> -21.25 | AO4: =VLOOKUP(B4, 'SEP25'!$A$1:$F$520, 6, FALSE) -> -15.75 | AP4: =VLOOKUP(B4, 'OCT25'!$A$1:$F$520, 5, FALSE) -> -8.5 | AQ4: =VLOOKUP(B4, 'NOV25'!$B$1:$I$616, 5, FALSE) -> -10.5 | AR4: =VLOOKUP(B4, 'DEC25'!$A$1:$I$611, 5, FALSE) -> -8 | AS4: =VLOOKUP(B4, 'JAN26'!$A$1:$I$607, 6, FALSE) -> -19
A5: GWI | B5: MI0004 - MP36 | C5: =-AVERAGE(AL5:AV5) -> 15.8125 | D5: -1.75 | E5: -4 | I5: -12.5 | J5: -10.25 | K5: -22.75 | L5: -33 | M5: -61.25 | N5: -37.75 | O5: -38.5 | P5: -6.5 | Q5: -27.75 | R5: -17.5 | S5: -15.5 | T5: -0.75 | U5: -2 | V5: -3.5 | W5: -6.5 | X5: -26.5 | Y5: -1.75 | Z5: -0.25 | AA5: -20.75 | AB5: -5 | AC5: -6 | AD5: =VLOOKUP(B5,'OCT24'!$A$1:H1176,6,0) -> -4 | AE5: =VLOOKUP(B5,'NOV24'!$A$1:H561,6,0) -> -7 | AF5: =VLOOKUP(B5,'DEC24'!$A$1:$H$914,5,0) -> -2.5 | AG5: =VLOOKUP(B5,'JAN25'!$A$1:G632,5,0) -> -13.25 | AH5: =VLOOKUP(B5,'FEB25'!A$1:G1066,5,0) -> -20.5 | AI5: =VLOOKUP(B5,'MAR25'!$A$1:G899,5,0) -> 0 | AJ5: =VLOOKUP(B5,'APR25'!$A$1:G528,5,0) -> -3.5 | AK5: =VLOOKUP(B5,'MAY25'!$A$1:G921,5,0) -> -17 | AL5: =VLOOKUP(B5,JUNE25!$A$1:G624,5,0) -> -34.25 | AM5: =VLOOKUP(B5, JULY25!$A$1:$E$544, 5, FALSE) -> -26 | AN5: =VLOOKUP(B5, 'AUG25'!$A$1:$E$540, 5, FALSE) -> -10.625 | AO5: =VLOOKUP(B5, 'SEP25'!$A$1:$F$520, 6, FALSE) -> -9 | AP5: =VLOOKUP(B5, 'OCT25'!$A$1:$F$520, 5, FALSE) -> -11 | AQ5: =VLOOKUP(B5, 'NOV25'!$B$1:$I$616, 5, FALSE) -> -13 | AR5: =VLOOKUP(B5, 'DEC25'!$A$1:$I$611, 5, FALSE) -> -7.5 | AS5: =VLOOKUP(B5, 'JAN26'!$A$1:$I$607, 6, FALSE) -> -15.125
A6: GWI | B6: MI0005 - BC36 | C6: =-AVERAGE(AL6:AV6) -> 33 | D6: -12 | E6: -27.75 | F6: -20 | G6: -12.25 | H6: -21.25 | I6: -11.5 | J6: -2 | K6: -23.75 | L6: -15.25 | M6: -4.5 | N6: -30.75 | O6: -13.25 | P6: -3.75 | Q6: -2 | R6: -8.75 | S6: -30 | T6: -3 | U6: -8 | V6: -24.25 | W6: -16.75 | X6: -17.5 | Y6: -5.5 | AA6: -22.25 | AD6: =VLOOKUP(B6,'OCT24'!$A$1:H1177,6,0) -> -30.5 | AE6: =VLOOKUP(B6,'NOV24'!$A$1:H562,6,0) -> -38.5 | AF6: =VLOOKUP(B6,'DEC24'!$A$1:$H$914,5,0) -> -32.75 | AG6: =VLOOKUP(B6,'JAN25'!$A$1:G633,5,0) -> -35.75 | AH6: =VLOOKUP(B6,'FEB25'!A$1:G1067,5,0) -> -27 | AJ6: =VLOOKUP(B6,'APR25'!$A$1:G529,5,0) -> -9 | AK6: =VLOOKUP(B6,'MAY25'!$A$1:G922,5,0) -> -20.5 | AL6: =VLOOKUP(B6,JUNE25!$A$1:G625,5,0) -> -10 | AM6: =VLOOKUP(B6, JULY25!$A$1:$E$544, 5, FALSE) -> -27.25 | AN6: =VLOOKUP(B6, 'AUG25'!$A$1:$E$540, 5, FALSE) -> -29.25 | AO6: =VLOOKUP(B6, 'SEP25'!$A$1:$F$520, 6, FALSE) -> -28 | AP6: =VLOOKUP(B6, 'OCT25'!$A$1:$F$520, 5, FALSE) -> -45.5 | AQ6: =VLOOKUP(B6, 'NOV25'!$B$1:$I$616, 5, FALSE) -> -58.75 | AR6: =VLOOKUP(B6, 'DEC25'!$A$1:$I$611, 5, FALSE) -> -25.5 | AS6: =VLOOKUP(B6, 'JAN26'!$A$1:$I$607, 6, FALSE) -> -39.75
A7: ALLMAX | B7: MI0006 - WVA29174 | C7: 0 | D7: 0 | E7: 0 | F7: 0 | G7: 0 | H7: 0 | I7: 0 | J7: 0 | K7: 0 | L7: 0 | M7: 0 | N7: 0 | O7: 0 | P7: 0 | Q7: 0 | R7: 0 | S7: 0 | T7: 0 | U7: 0 | V7: 0 | W7: 0 | X7: 0 | Y7: 0 | Z7: 0
A8: ALLMAX | B8: MI0007 - WVA29087-GOLD | C8: 0 | D8: 0 | E8: 0 | F8: 0 | G8: 0 | H8: 0 | I8: 0 | J8: 0 | K8: 0 | L8: 0 | M8: 0 | N8: 0 | O8: 0 | P8: 0 | Q8: 0 | R8: 0 | S8: 0 | T8: 0 | U8: 0 | V8: 0 | W8: 0 | X8: 0 | Y8: 0 | Z8: 0
A9: AIRBAGS | B9: MI0008 - 996075-K AIRBAG VOLVO O/M 1076076 | C9: =-AVERAGE(AL9:AV9) -> 0 | D9: 0 | E9: 0 | F9: 0 | G9: 0 | H9: 0 | I9: 0 | J9: 0 | K9: 0 | L9: 0 | M9: 0 | N9: 0 | O9: 0 | P9: 0 | Q9: 0 | R9: 0 | S9: 0 | T9: 0 | U9: 0 | V9: 0 | W9: 0 | X9: 0 | Y9: 0 | Z9: 0 | AA9: 0 | AB9: 0 | AC9: 0 | AD9: =VLOOKUP(B9,'OCT24'!$A$1:H1180,6,0) -> 0 | AE9: =VLOOKUP(B9,'NOV24'!$A$1:H565,6,0) -> 0 | AF9: =VLOOKUP(B9,'DEC24'!$A$1:$H$914,5,0) -> 0 | AG9: =VLOOKUP(B9,'JAN25'!$A$1:G636,5,0) -> 0 | AH9: =VLOOKUP(B9,'FEB25'!A$1:G1070,5,0) -> 0 | AI9: =VLOOKUP(B9,'MAR25'!$A$1:G903,5,0) -> 0 | AJ9: =VLOOKUP(B9,'APR25'!$A$1:G532,5,0) -> 0 | AK9: =VLOOKUP(B9,'MAY25'!$A$1:G925,5,0) -> 0 | AL9: =VLOOKUP(B9,JUNE25!$A$1:G628,5,0) -> 0 | AM9: =VLOOKUP(B9, JULY25!$A$1:$E$544, 5, FALSE) -> 0 | AN9: =VLOOKUP(B9, 'AUG25'!$A$1:$E$540, 5, FALSE) -> 0 | AO9: =VLOOKUP(B9, 'SEP25'!$A$1:$F$520, 6, FALSE) -> - | AP9: =VLOOKUP(B9, 'OCT25'!$A$1:$F$520, 5, FALSE) -> - | AQ9: =VLOOKUP(B9, 'NOV25'!$B$1:$I$616, 5, FALSE) -> - | AR9: =VLOOKUP(B9, 'DEC25'!$A$1:$I$611, 5, FALSE) -> - | AS9: =VLOOKUP(B9, 'JAN26'!$A$1:$I$607, 6, FALSE) -> -
A10: AIRBAGS | B10: MI0009 - 994713-K AIRBAG VOLVO O/M 1076595 | C10: =-AVERAGE(AL10:AV10) -> 2.6666667 | D10: -16 | E10: -1 | F10: -1 | G10: -6 | H10: 0 | I10: -3 | J10: 0 | K10: -19 | L10: 0 | M10: 0 | N10: -5 | O10: -11 | P10: -9 | Q10: -8 | R10: -8 | S10: -6 | T10: -1 | U10: -2 | V10: 0 | W10: 0 | X10: 0 | Y10: 0 | Z10: 0 | AA10: -1 | AB10: 0 | AC10: 0 | AD10: =VLOOKUP(B10,'OCT24'!$A$1:H1181,6,0) -> -1 | AE10: =VLOOKUP(B10,'NOV24'!$A$1:H566,6,0) -> 0 | AF10: =VLOOKUP(B10,'DEC24'!$A$1:$H$914,5,0) -> 0 | AG10: =VLOOKUP(B10,'JAN25'!$A$1:G637,5,0) -> 0 | AH10: =VLOOKUP(B10,'FEB25'!A$1:G1071,5,0) -> 0 | AI10: =VLOOKUP(B10,'MAR25'!$A$1:G904,5,0) -> -2 | AJ10: =VLOOKUP(B10,'APR25'!$A$1:G533,5,0) -> 0 | AK10: =VLOOKUP(B10,'MAY25'!$A$1:G926,5,0) -> -6 | AL10: =VLOOKUP(B10,JUNE25!$A$1:G629,5,0) -> -6 | AM10: =VLOOKUP(B10, JULY25!$A$1:$E$544, 5, FALSE) -> -2 | AN10: =VLOOKUP(B10, 'AUG25'!$A$1:$E$540, 5, FALSE) -> 0 | AO10: =VLOOKUP(B10, 'SEP25'!$A$1:$F$520, 6, FALSE) -> - | AP10: =VLOOKUP(B10, 'OCT25'!$A$1:$F$520, 5, FALSE) -> - | AQ10: =VLOOKUP(B10, 'NOV25'!$B$1:$I$616, 5, FALSE) -> - | AR10: =VLOOKUP(B10, 'DEC25'!$A$1:$I$611, 5, FALSE) -> - | AS10: =VLOOKUP(B10, 'JAN26'!$A$1:$I$607, 6, FALSE) -> -
A11: AIRBAGS | B11: MI0010 - 994913-K AIRBAG SCA 124 DIFF / 9881 | C11: =-AVERAGE(AL11:AV11) -> 2.25 | D11: 0 | E11: 0 | F11: -1 | G11: -16 | H11: -1 | I11: 0 | J11: -13 | K11: 0 | L11: 0 | M11: -8 | N11: -1 | O11: -1 | P11: -3 | Q11: -1 | R11: 0 | S11: 0 | T11: -1 | U11: 0 | V11: 0 | W11: 0 | X11: 0 | Y11: 0 | Z11: 0 | AA11: -4 | AB11: 0 | AC11: -1 | AD11: =VLOOKUP(B11,'OCT24'!$A$1:H1182,6,0) -> 0 | AE11: =VLOOKUP(B11,'NOV24'!$A$1:H567,6,0) -> 0 | AF11: =VLOOKUP(B11,'DEC24'!$A$1:$H$914,5,0) -> -1 | AG11: =VLOOKUP(B11,'JAN25'!$A$1:G638,5,0) -> 0 | AH11: =VLOOKUP(B11,'FEB25'!A$1:G1072,5,0) -> 0 | AI11: =VLOOKUP(B11,'MAR25'!$A$1:G905,5,0) -> -2 | AJ11: =VLOOKUP(B11,'APR25'!$A$1:G534,5,0) -> 0 | AK11: =VLOOKUP(B11,'MAY25'!$A$1:G927,5,0) -> -1 | AL11: =VLOOKUP(B11,JUNE25!$A$1:G630,5,0) -> -2 | AM11: =VLOOKUP(B11, JULY25!$A$1:$E$544, 5, FALSE) -> -1 | AN11: =VLOOKUP(B11, 'AUG25'!$A$1:$E$540, 5, FALSE) -> -2 | AO11: =VLOOKUP(B11, 'SEP25'!$A$1:$F$520, 6, FALSE) -> -3 | AP11: =VLOOKUP(B11, 'OCT25'!$A$1:$F$520, 5, FALSE) -> -3 | AQ11: =VLOOKUP(B11, 'NOV25'!$B$1:$I$616, 5, FALSE) -> -3 | AR11: =VLOOKUP(B11, 'DEC25'!$A$1:$I$611, 5, FALSE) -> -2 | AS11: =VLOOKUP(B11, 'JAN26'!$A$1:$I$607, 6, FALSE) -> -2
A12: AIRBAGS | B12: MI0011 - 999780-K AIRBAG FREIGHTLINER METAL | C12: =-AVERAGE(AL12:AV12) -> 4.75 | D12: -21 | E12: -34 | F12: -22 | G12: -17 | H12: -31 | I12: -27 | J12: -36 | K12: -16 | L12: -8 | M12: -18 | N12: -21 | O12: -22 | P12: -12 | Q12: -16 | R12: -13 | S12: -15 | T12: -3 | U12: 0 | V12: -5 | W12: 0 | X12: 0 | Y12: -5 | Z12: -2 | AA12: -1 | AB12: -4 | AC12: -1 | AD12: =VLOOKUP(B12,'OCT24'!$A$1:H1183,6,0) -> -9 | AE12: =VLOOKUP(B12,'NOV24'!$A$1:H568,6,0) -> -22 | AF12: =VLOOKUP(B12,'DEC24'!$A$1:$H$914,5,0) -> -18 | AG12: =VLOOKUP(B12,'JAN25'!$A$1:G639,5,0) -> -13 | AH12: =VLOOKUP(B12,'FEB25'!A$1:G1073,5,0) -> 0 | AI12: =VLOOKUP(B12,'MAR25'!$A$1:G906,5,0) -> -5 | AJ12: =VLOOKUP(B12,'APR25'!$A$1:G535,5,0) -> -15 | AK12: =VLOOKUP(B12,'MAY25'!$A$1:G928,5,0) -> -7 | AL12: =VLOOKUP(B12,JUNE25!$A$1:G631,5,0) -> -1 | AM12: =VLOOKUP(B12, JULY25!$A$1:$E$544, 5, FALSE) -> -11 | AN12: =VLOOKUP(B12, 'AUG25'!$A$1:$E$540, 5, FALSE) -> -2 | AO12: =VLOOKUP(B12, 'SEP25'!$A$1:$F$520, 6, FALSE) -> -9 | AP12: =VLOOKUP(B12, 'OCT25'!$A$1:$F$520, 5, FALSE) -> -1 | AQ12: =VLOOKUP(B12, 'NOV25'!$B$1:$I$616, 5, FALSE) -> -8 | AR12: =VLOOKUP(B12, 'DEC25'!$A$1:$I$611, 5, FALSE) -> -5 | AS12: =VLOOKUP(B12, 'JAN26'!$A$1:$I$607, 6, FALSE) -> -1
A13: SPARES | B13: MI00117 - Z SPRING BPW | C13: 0 | D13: 0 | E13: 0 | F13: 0 | G13: 0 | H13: 0 | I13: 0 | J13: 0 | K13: 0 | L13: 0 | M13: 0 | N13: 0 | O13: 0 | P13: 0 | Q13: 0 | R13: 0 | S13: 0 | T13: 0 | U13: 0 | V13: 0 | W13: 0 | X13: 0 | Y13: 0 | Z13: 0
A14: AIRBAGS | B14: MI0012 - 999780-K-PP AIRBAG FREIGHTLINER | C14: 0 | D14: 0 | E14: 0 | F14: 0 | G14: 0 | H14: 0 | I14: 0 | J14: 0 | K14: 0 | L14: 0 | M14: 0 | N14: 0 | O14: 0 | P14: 0 | Q14: 0 | R14: 0 | S14: 0 | T14: 0 | U14: 0 | V14: 0 | W14: 0 | X14: 0 | Y14: 0 | Z14: 0
A15: AIRBAGS | B15: MI0013 - 994183-24K AIRBAG BENZ | C15: =-AVERAGE(AL15:AV15) -> 0 | D15: 0 | E15: 0 | F15: 0 | G15: 0 | H15: 0 | I15: 0 | J15: 0 | K15: 0 | L15: 0 | M15: 0 | N15: 0 | O15: 0 | P15: 0 | Q15: 0 | R15: 0 | S15: 0 | T15: 0 | U15: 0 | V15: 0 | W15: 0 | X15: 0 | Y15: 0 | Z15: 0 | AI15: =VLOOKUP(B15,'MAR25'!$A$1:G909,5,0) -> -14 | AJ15: =VLOOKUP(B15,'APR25'!$A$1:G538,5,0) -> 0 | AK15: =VLOOKUP(B15,'MAY25'!$A$1:G931,5,0) -> 0 | AL15: =VLOOKUP(B15,JUNE25!$A$1:G634,5,0) -> 0 | AM15: =VLOOKUP(B15, JULY25!$A$1:$E$544, 5, FALSE) -> 0 | AN15: =VLOOKUP(B15, 'AUG25'!$A$1:$E$540, 5, FALSE) -> 0 | AO15: =VLOOKUP(B15, 'SEP25'!$A$1:$F$520, 6, FALSE) -> - | AP15: =VLOOKUP(B15, 'OCT25'!$A$1:$F$520, 5, FALSE) -> - | AQ15: =VLOOKUP(B15, 'NOV25'!$B$1:$I$616, 5, FALSE) -> - | AR15: =VLOOKUP(B15, 'DEC25'!$A$1:$I$611, 5, FALSE) -> - | AS15: =VLOOKUP(B15, 'JAN26'!$A$1:$I$607, 6, FALSE) -> -
A16: AIRBAGS | B16: MI0014 - 994757-02K AIRBAG BENZ | C16: 0 | D16: 0 | E16: 0 | F16: 0 | G16: 0 | H16: 0 | I16: 0 | J16: 0 | K16: 0 | L16: 0 | M16: 0 | N16: 0 | O16: 0 | P16: 0 | Q16: 0 | R16: 0 | S16: 0 | T16: 0 | U16: 0 | V16: 0 | W16: 0 | X16: 0 | Y16: 0 | Z16: 0
A17: AIRBAGS | B17: MI0015 - 346418K AIRBAG VOLVO N/M | C17: 0 | D17: 0 | E17: 0 | F17: 0 | G17: 0 | H17: 0 | I17: 0 | J17: 0 | K17: 0 | L17: 0 | M17: 0 | N17: 0 | O17: 0 | P17: 0 | Q17: 0 | R17: 0 | S17: 0 | T17: 0 | U17: 0 | V17: 0 | W17: 0 | X17: 0 | Y17: 0 | Z17: 0
A18: AIRBAGS | B18: MI0016 - 6356418-K AIRBAG VOLVO N/M | C18: 0 | D18: 0 | E18: 0 | F18: 0 | G18: 0 | H18: 0 | I18: 0 | J18: 0 | K18: 0 | L18: 0 | M18: 0 | N18: 0 | O18: 0 | P18: 0 | Q18: 0 | R18: 0 | S18: 0 | T18: 0 | U18: 0 | V18: 0 | W18: 0 | X18: 0 | Y18: 0 | Z18: 0
A19: AIRBAGS | B19: MI0017 - E10.7803.C AIRBAG VOLVO N/M | C19: 0 | D19: 0 | E19: 0 | F19: 0 | G19: 0 | H19: 0 | I19: 0 | J19: 0 | K19: 0 | L19: 0 | M19: 0 | N19: 0 | O19: 0 | P19: 0 | Q19: 0 | R19: 0 | S19: 0 | T19: 0 | U19: 0 | V19: 0 | W19: 0 | X19: 0 | Y19: 0 | Z19: 0
A20: SPARES | B20: MI0018 - BPW SPRING LONG | C20: =-AVERAGE(AL20:AV20) -> 8.75 | D20: -50 | E20: -12 | F20: -6 | G20: -6 | H20: -8 | I20: -37 | J20: -21 | K20: -62 | L20: -3 | M20: -6 | N20: -4 | O20: 0 | P20: 0 | Q20: 0 | R20: -20 | S20: 0 | T20: 0 | U20: -10 | V20: 0 | W20: -50 | X20: 0 | Y20: -115 | Z20: -23 | AA20: 0 | AB20: 0 | AC20: 0 | AD20: =VLOOKUP(B20,'OCT24'!$A$1:H1191,6,0) -> 0 | AE20: =VLOOKUP(B20,'NOV24'!$A$1:H576,6,0) -> -2 | AF20: =VLOOKUP(B20,'DEC24'!$A$1:$H$914,5,0) -> 0 | AG20: =VLOOKUP(B20,'JAN25'!$A$1:G647,5,0) -> -26 | AH20: =VLOOKUP(B20,'FEB25'!A$1:G1081,5,0) -> -1 | AI20: =VLOOKUP(B20,'MAR25'!$A$1:G914,5,0) -> -20 | AJ20: =VLOOKUP(B20,'APR25'!$A$1:G543,5,0) -> -1 | AK20: =VLOOKUP(B20,'MAY25'!$A$1:G936,5,0) -> 0 | AL20: =VLOOKUP(B20,JUNE25!$A$1:G639,5,0) -> -2 | AM20: =VLOOKUP(B20, JULY25!$A$1:$E$544, 5, FALSE) -> 0 | AN20: =VLOOKUP(B20, 'AUG25'!$A$1:$E$540, 5, FALSE) -> -18 | AO20: =VLOOKUP(B20, 'SEP25'!$A$1:$F$520, 6, FALSE) -> -1 | AP20: =VLOOKUP(B20, 'OCT25'!$A$1:$F$520, 5, FALSE) -> -7 | AQ20: =VLOOKUP(B20, 'NOV25'!$B$1:$I$616, 5, FALSE) -> -26 | AR20: =VLOOKUP(B20, 'DEC25'!$A$1:$I$611, 5, FALSE) -> -5 | AS20: =VLOOKUP(B20, 'JAN26'!$A$1:$I$607, 6, FALSE) -> -11
A21: SPARES | B21: MI0019 - OIL SEAL 125 X 150 X 13 | C21: =-AVERAGE(AL21:AV21) -> 3 | D21: 0 | E21: 0 | F21: 0 | G21: 0 | H21: 0 | I21: 0 | J21: 0 | K21: 0 | L21: 0 | M21: 0 | N21: 0 | O21: 0 | P21: 0 | Q21: 0 | R21: 0 | S21: 0 | T21: 0 | U21: 0 | V21: 0 | W21: 0 | X21: 0 | Y21: 0 | Z21: 0 | AA21: 0 | AB21: 0 | AC21: 0 | AD21: =VLOOKUP(B21,'OCT24'!$A$1:H1192,6,0) -> 0 | AE21: =VLOOKUP(B21,'NOV24'!$A$1:H577,6,0) -> 0 | AF21: =VLOOKUP(B21,'DEC24'!$A$1:$H$914,5,0) -> 0 | AG21: =VLOOKUP(B21,'JAN25'!$A$1:G648,5,0) -> 0 | AH21: =VLOOKUP(B21,'FEB25'!A$1:G1082,5,0) -> 0 | AI21: =VLOOKUP(B21,'MAR25'!$A$1:G915,5,0) -> 0 | AJ21: =VLOOKUP(B21,'APR25'!$A$1:G544,5,0) -> 0 | AK21: =VLOOKUP(B21,'MAY25'!$A$1:G937,5,0) -> 0 | AL21: =VLOOKUP(B21,JUNE25!$A$1:G640,5,0) -> -4 | AM21: =VLOOKUP(B21, JULY25!$A$1:$E$544, 5, FALSE) -> -1 | AN21: =VLOOKUP(B21, 'AUG25'!$A$1:$E$540, 5, FALSE) -> -5 | AO21: =VLOOKUP(B21, 'SEP25'!$A$1:$F$520, 6, FALSE) -> -1 | AP21: =VLOOKUP(B21, 'OCT25'!$A$1:$F$520, 5, FALSE) -> -6 | AQ21: =VLOOKUP(B21, 'NOV25'!$B$1:$I$616, 5, FALSE) -> - | AR21: =VLOOKUP(B21, 'DEC25'!$A$1:$I$611, 5, FALSE) -> -1 | AS21: =VLOOKUP(B21, 'JAN26'!$A$1:$I$607, 6, FALSE) -> -
B22: MI0020 - E500HD129 | C22: 0 | D22: 0 | E22: 0 | F22: 0 | G22: 0 | H22: 0 | I22: -2 | J22: 0 | K22: 0 | L22: 0 | M22: 0 | N22: 0 | O22: 0 | P22: 0 | Q22: 0 | R22: 0 | S22: 0 | T22: 0 | U22: 0 | V22: 0 | W22: 0 | X22: 0 | Y22: 0 | Z22: 0
B23: MI0021 - H24W05 | C23: =-AVERAGE(AL23:AV23) -> 0 | D23: 0 | E23: 0 | F23: 0 | G23: 0 | H23: 0 | I23: 0 | J23: 0 | K23: 0 | L23: 0 | M23: 0 | N23: 0 | O23: 0 | P23: 0 | Q23: 0 | R23: 0 | S23: 0 | T23: 0 | U23: 0 | V23: 0 | W23: 0 | X23: 0 | Y23: 0 | Z23: 0 | AA23: 0 | AB23: 0 | AC23: 0 | AD23: =VLOOKUP(B23,'OCT24'!$A$1:H1194,6,0) -> 0 | AE23: =VLOOKUP(B23,'NOV24'!$A$1:H579,6,0) -> 0 | AF23: =VLOOKUP(B23,'DEC24'!$A$1:$H$914,5,0) -> 0 | AG23: =VLOOKUP(B23,'JAN25'!$A$1:G650,5,0) -> 0 | AH23: =VLOOKUP(B23,'FEB25'!A$1:G1084,5,0) -> 0 | AI23: =VLOOKUP(B23,'MAR25'!$A$1:G917,5,0) -> 0 | AJ23: =VLOOKUP(B23,'APR25'!$A$1:G546,5,0) -> 0 | AK23: =VLOOKUP(B23,'MAY25'!$A$1:G939,5,0) -> 0 | AL23: =VLOOKUP(B23,JUNE25!$A$1:G642,5,0) -> 0 | AM23: =VLOOKUP(B23, JULY25!$A$1:$E$544, 5, FALSE) -> 0 | AN23: =VLOOKUP(B23, 'AUG25'!$A$1:$E$540, 5, FALSE) -> 0 | AO23: =VLOOKUP(B23, 'SEP25'!$A$1:$F$520, 6, FALSE) -> - | AP23: =VLOOKUP(B23, 'OCT25'!$A$1:$F$520, 5, FALSE) -> - | AQ23: =VLOOKUP(B23, 'NOV25'!$B$1:$I$616, 5, FALSE) -> - | AR23: =VLOOKUP(B23, 'DEC25'!$A$1:$I$611, 5, FALSE) -> - | AS23: =VLOOKUP(B23, 'JAN26'!$A$1:$I$607, 6, FALSE) -> -
